Workbook
Name jmp: '[1]PAGAR SLIP'!$AT$18:$CH$36
Name km: #REF!
Name nil: '[1]pre calculation OLD'!$L$1
Name RR: '[1]All Teacher Data'!$B$2:$DE$271
Name tod: '[1]PAGAR SLIP'!$AF$7:$AF$18
Name un_lock: #REF!
Name Z_4D48DB91_7DAB_41A4_B943_A0175ADDFF54_.wvu.Cols: 'કપાટ પત્રક પેહલા ભરવુ '!#REF!
Name Z_4D48DB91_7DAB_41A4_B943_A0175ADDFF54_.wvu.Cols: 'જૂન સ્લેબ મુજબ (OLD SLAB)'!$AH:$AV
Name Z_4D48DB91_7DAB_41A4_B943_A0175ADDFF54_.wvu.Cols: 'નવા સ્લેબ મુજબ (NEW SLAB)'!$AH:$AV
Name Z_4D48DB91_7DAB_41A4_B943_A0175ADDFF54_.wvu.PrintArea: 'કપાટ પત્રક પેહલા ભરવુ '!$C$2:$N$30
Name Z_4D48DB91_7DAB_41A4_B943_A0175ADDFF54_.wvu.PrintArea: 'જૂન સ્લેબ મુજબ (OLD SLAB)'!$D$2:$AE$60
Name Z_4D48DB91_7DAB_41A4_B943_A0175ADDFF54_.wvu.PrintArea: 'નવા સ્લેબ મુજબ (NEW SLAB)'!$D$2:$AE$62
Name Z_4D48DB91_7DAB_41A4_B943_A0175ADDFF54_.wvu.Rows: 'કપાટ પત્રક પેહલા ભરવુ '!$31:$65521
Name Z_5EABC722_00BF_4383_B8A6_CD92B28655DC_.wvu.PrintArea: 'કપાટ પત્રક પેહલા ભરવુ '!$C$2:$N$30
Name Z_9BFE08BE_8D51_4068_A1B5_89EAA963583E_.wvu.Cols: 'કપાટ પત્રક પેહલા ભરવુ '!#REF!
Name Z_9BFE08BE_8D51_4068_A1B5_89EAA963583E_.wvu.Cols: 'જૂન સ્લેબ મુજબ (OLD SLAB)'!$AH:$AV
Name Z_9BFE08BE_8D51_4068_A1B5_89EAA963583E_.wvu.Cols: 'નવા સ્લેબ મુજબ (NEW SLAB)'!$AH:$AV
Name Z_9BFE08BE_8D51_4068_A1B5_89EAA963583E_.wvu.PrintArea: 'કપાટ પત્રક પેહલા ભરવુ '!$C$2:$N$30
Name Z_9BFE08BE_8D51_4068_A1B5_89EAA963583E_.wvu.PrintArea: 'જૂન સ્લેબ મુજબ (OLD SLAB)'!$D$2:$AE$60
Name Z_9BFE08BE_8D51_4068_A1B5_89EAA963583E_.wvu.PrintArea: 'નવા સ્લેબ મુજબ (NEW SLAB)'!$D$2:$AE$62
Name Z_9BFE08BE_8D51_4068_A1B5_89EAA963583E_.wvu.Rows: 'કપાટ પત્રક પેહલા ભરવુ '!$31:$65521

Sheet જૂન સ્લેબ મુજબ (OLD SLAB)
A1: NPS માં રોકાણ બતાવવાનું છે ? >>> | K1: ના | N1: સી.પી.એફ. કે જી.પી.એફ. છો ? સીલેક્ટ કરો -->>> | AC1: C.P.F.
C2: ઈન્કમટેક્ષ ગણતરી દર્શાવતુ પત્રક નાંણાકીય વર્ષ : ૨૦૨૩-૨૦૨૪ - OLD REGIME | AM2: C.P.F. | AN2: =AO32 -> 0 | AO2: 0 | AP2: =IF(AC1="C.P.F.",AN2,AO2) -> 0 | AQ2: =AN32 -> 0 | AR2: =IF(AC1="C.P.F.",AQ2,AO2) -> 0
C3: નાંણાકીય વર્ષ ૨૦૨૩-૨૪ | V3: આકારણી વર્ષ ૨૦૨૪-૨૫ | AM3: G.P.F. | AN3: ='કપાટ પત્રક પેહલા ભરવુ '!G18 -> 0 | AO3: 0 | AP3: =IF(AC1="G.P.F.",AN3,AO3) -> 0
C4: Mobile No | R4: Pan No.
C6: Adhar No. | R6: Date of Birth
C8: (૧) કર્મચારીનું પુરૂ નામ. | X8: હોદ્દો
C9: (૨) ઓફીસ/પે.કેન્દ્રનું નામ. | V9: બેંક ખાતા નંબર
C10: (૩) બેંકનું નામ. | P10: શાખા. | V10: બેંક IFSC Code:
C13: (૧). | D13: આવક (વાર્ષિક પગાર સાથે) : | Z13: રૂ! | AA13: ='કપાટ પત્રક પેહલા ભરવુ '!E25 -> 0
C14: (૨). | D14: બાદ (-) | F14: (A) | G14: સ્ટાન્ડર્ડ ડીડક્શન ( કલમ ૧૬ ) | R14: રૂ! | S14: 50000
F15: (B) | G15: વ્યવસાય વેરો | R15: રૂ! | S15: ='કપાટ પત્રક પેહલા ભરવુ '!F18 -> 0
F16: (C) | G16: મકાન લોનનું વ્યાજ ( ૨,૦૦,૦૦૦ સુધી) | R16: રૂ! | S16: =Y78 -> 0
F17: (D) | G17: અન્ય | R17: રૂ! | S17: 0
F18: (E) | G18: અન્ય | R18: રૂ! | S18: 0 | W18: (A+B+C+D+E) | Z18: રૂ! | AA18: =SUM(S14:V18) -> 50000
C19: (૩). | D19: કોલમ (૧) બાદ કોલમ (૨) | Z19: રૂ! | AA19: =AA13-AA18 -> -50000 | AM19: =SUM(L21:N27)+SUM(X21:Z27) -> 0
C20: (૪). | D20: બાદ કપાતો ( કલમ ૮૦ સી મુજબ )
D21: (A) | E21: જી.પી.એફ. | K21: રૂ! | L21: =AP3 -> 0 | P21: (H) | Q21: શિક્ષણ ફી (ભારતીય સંસ્થા) | W21: રૂ! | X21: 0 | AM21: =SUM(L21:N27) -> 0 | AN21: 50000 | AO21: =SUM(AM21:AN21) -> 50000
D22: (B) | E22: સી.પી.એફ. | K22: રૂ! | L22: =AP2 -> 0 | P22: (I) | Q22: પી.પી.એફ. | W22: રૂ! | X22: 0 | AM22: ='કપાટ પત્રક પેહલા ભરવુ '!H18 -> 0
D23: (C) | E23: જુથ વિમો | K23: રૂ! | L23: ='કપાટ પત્રક પેહલા ભરવુ '!I18 -> 0 | P23: (J) | Q23: એન.એસ.સી. | W23: રૂ! | X23: 0
D24: (D) | E24: એલ.આઈ.સી.(પગારથી કપાત) | K24: રૂ! | L24: ='કપાટ પત્રક પેહલા ભરવુ '!K18 -> 0 | P24: (K) | Q24: બેંક એફ. ડી. (૫ વર્ષની જ) | W24: રૂ! | X24: 0
D25: (E) | E25: એલ.આઈ.સી.ડાયરેક્ટ | K25: રૂ! | L25: 0 | P25: (L) | Q25: સુકન્યા સમૃધી યોજના | W25: રૂ! | X25: 0
D26: (F) | E26: મકાનલોન મુદ્દલ | K26: રૂ! | L26: ='કપાટ પત્રક પેહલા ભરવુ '!M18 -> 0 | P26: (M) | Q26: ટેક્ષ સેવર મ્યુચુઅલ ફંડ | W26: રૂ! | X26: 0
D27: (G) | E27: પી.એલ.આઈ. | K27: રૂ! | L27: ='કપાટ પત્રક પેહલા ભરવુ '!N18 -> 0 | P27: (N) | W27: રૂ! | X27: 0
C29: ( A to N ) કુલ સરવાળો દોઢ લાખ સુધી | P29: રૂ! | Q29: =AM33 -> 0 | AM29: =L21+AM22+L23+L24+L25+L26+L27 -> 0 | AN29: =SUM(X21:Z27) -> 0 | AO29: =SUM(AM29:AN29) -> 0
D31: (O) | E31: કલમ ૮૦ ડી મેડીક્લેઈમ ( ૨૫૦૦૦ સુધી ) | R31: રૂ! | S31: 0 | AM31: =IF(AO29>150000,150000,AO29) -> 0 | AN31: =IF(AO29>AM31,AO29-AM31,"") | AO31: =IF(AP31>50000,50000,AP31) -> 0 | AP31: =IF(AN31>AM22,AM22,AN31) -> 0
D32: (P) | E32: કલમ ૮૦ ડી.ડી.અપંગ આશ્રિત | R32: રૂ! | S32: 0 | AM32: =IF(AP31>50000,AM22-AO31,AM22-AP31) -> 0 | AN32: =IF(K1="ના",0,AO31) -> 0 | AO32: =IF(K1="ના",AM22,AM32) -> 0
D33: (Q) | E33: કલમ ૮૦ ડીડીબી ગંભીર રોગ | R33: રૂ! | S33: 0 | AM33: =IF(AM19<150000,AM19,AM31) -> 0
D34: (R) | E34: કલમ ૮૦ સીસીડી ૧ (બી) એન.પી.એસ.( રૂ. 50000/- સુધી) | R34: રૂ! | S34: =AR2 -> 0
D35: (S) | E35: કલમ ૮૦ ઈ ઉચ્ચ શિક્ષણ લોન વ્યાજ | R35: રૂ! | S35: 0
D36: (T) | E36: કલમ ૮૦ જી દાન (પાછળ સુચના ૫ પ્રમાણે) | R36: રૂ! | S36: 0
D37: (U) | E37: કલમ ૮૦ જીજીસી રાજકીય પાર્ટીને દાન | R37: રૂ! | S37: 0
D38: (V) | E38: કલમ ૮૦ યુ અપંગ વ્યક્તિ | R38: રૂ! | S38: 0
D39: (W) | R39: રૂ! | S39: 0 | W39: (A to W) કુલ સરવાળો | AB39: =SUM(Q29+S31+S32+S33+S34+S35+S36+S37+S38+S39) -> 0
C41: (૫). | D41: કોલમ ૩ બાદ કોલમ ૪ | Q41: (ઈન્કમટેક્ષ પાત્ર રકમ ) | Y41: રૂ! | Z41: =AA19-AB39 -> -50000
C42: (૬). | D42: ભરવા પાત્ર ઈન્કમટેક્ષ
E43: (૧). | F43: રૂ! | G43: ૨,૫૦,૦૦૦ | J43: સુધી | R43: રૂ! | S43: NIL
E44: (૨). | F44: રૂ! | G44: ૨,૫૦,૦૦૧ | J44: થી | K44: ૫,૦૦,૦૦૦ સુધી ૫ ટકા | R44: રૂ! | S44: =AA67 -> 0
E45: (૩). | F45: રૂ! | G45: ૫,૦૦,૦૦૧ | J45: થી | K45: ૧૦,૦૦,૦૦૦ સુધી ૨૦ ટકા | R45: રૂ! | S45: =AA68 -> 0
E46: (૪). | F46: રૂ! | G46: ૧૦,૦૦,૦૦૧ | J46: થી | K46: વધુ....................૩૦ ટકા | R46: રૂ! | S46: =AA69 -> 0
C48: ૧ થી ૪ કુલ આવકવેરા (ઈન્કમટેક્ષ) | Z48: રૂ! | AA48: =ROUND(SUM(S44:V46),0) -> 0
...

Sheet કપાટ પત્રક પેહલા ભરવુ 
A1: આપની ઈન્કમટેક્ષ પાત્ર રકમ ->>>> | G1: new | H1: =X6 -> અંકે રૂપિયા પુરા | XFD1: દ1
C3: કર્મ ચારીનું નામ :- | F3: =IF('નવા સ્લેબ મુજબ (NEW SLAB)'!I8="","",'નવા સ્લેબ મુજબ (NEW SLAB)'!I8) | J3: શાળાનું નામ :- | L3: =IF('નવા સ્લેબ મુજબ (NEW SLAB)'!I9="","",'નવા સ્લેબ મુજબ (NEW SLAB)'!I9)
C5: માસ | E5: ગ્રોસ પગાર | F5: વ્યવસાય વેરો રૂl. | G5: G.P.F રૂપિયા | H5: C.P.F રૂપિયા | I5: જૂથ વિમો રૂl. | J5: પગારમાંથી TDS INCOME-TAX | K5: એલ.આઈ.સી પગારમાંથી રૂl. | L5: મકાન લોન વ્યાજ રૂl. | M5: મકાન લોન મુદલ રૂl. | N5: P.L.I.
C6: માર્ચ-૨૩ | R6: new | S6: =Sheet1!A12 -> અંકે રૂપિયા પુરા | X6: =IF(G1="new",S6,S7) -> અંકે રૂપિયા પુરા
C7: એપ્રિલ-૨૩ | R7: old | S7: =Sheet1!A25 -> અંકે રૂપિયા પુરા
C8: મે-૨૩
C9: જુન-૨૩
C10: જુલાઈ-૨૩ | S10: =SUM(J6:J16) -> 0
C11: ઓગષ્ટ-૨૩
C12: સપ્ટે-૨૩
C13: ઓક્ટોબર-૨૩
C14: નવેમ્બર-૨૩
C15: ડીસેમ્બર-૨૩
C16: જાન્યુઆરી-૨૪
C17: ફેબ્રુઆરી-૨૪
C18: (A) કુલ રૂl. | E18: =SUM(E6:E17) -> 0 | F18: =SUM(F6:F17) -> 0 | G18: =SUM(G6:G17) -> 0 | H18: =SUM(H6:H17) -> 0 | I18: =SUM(I6:I17) -> 0 | J18: =SUM(J6:J17) -> 0 | K18: =SUM(K6:K17) -> 0 | L18: =SUM(L6:L17) -> 0 | ... N18: =SUM(N6:N17) -> 0
C20: ( B ) | D20: રૂl. | F20: એરીયર્સ
C21: ( C ) | D21: રૂl. | F21: એરીયર્સ
C22: ( D ) | D22: રૂl. | F22: મોંઘવારી
C23: ( E ) | D23: રૂl. | F23: અન્ય
J24: નોંધ:
D25: રૂl. | E25: =SUM(E18+E20+E21+E22+E23) -> 0 | G25: A થી E નો કુલ સરવાળો કુલ વાર્ષિક આવક | J25: આ ફોર્મમાં દર્શાવેલ તમામ માહિતી સાચી અને રેકર્ડ ઉપરથી ચકાસીને રજુ કરેલ છે. આ માહિતી ખોટી પુરવાર થશે, તે બાબતે પુર્તતા કરવાની જવાબદારી મારી રહેશે.
J26: X
K27: કર્મચારીની સહી
C28: ઉપરોક્ત કર્મચારીને નાણાંકીય વર્ષ | G28: 2023 / 2024
C30: તારીખ:

Sheet નવા સ્લેબ મુજબ (NEW SLAB)
A1: C.P.F. ખાતુ હોયતો હા સિલેક્ટ કરો | K1: હા | M1: ના | O1: સી.પી.એફ. કે જી.પી.એફ. છો ? સીલેક્ટ કરો -->>> | AC1: G.P.F.
C2: ઈન્કમટેક્ષ ગણતરી દર્શાવતુ પત્રક નાંણાકીય વર્ષ : 2023-2024 - NEW REGIME | AM2: C.P.F. | AN2: =AO32 -> 0 | AO2: 0 | AP2: =IF(AC1="C.P.F.",AN2,AO2) -> 0 | AQ2: =AN32 -> 0 | AR2: =IF(AC1="C.P.F.",AQ2,AO2) -> 0
C3: નાંણાકીય વર્ષ 2023-24 | V3: આકારણી વર્ષ 2024-25 | AM3: G.P.F. | AN3: ='કપાટ પત્રક પેહલા ભરવુ '!G18 -> 0 | AO3: 0 | AP3: =IF(AC1="G.P.F.",AN3,AO3) -> 0
C4: Mobile No | F4: =IF('જૂન સ્લેબ મુજબ (OLD SLAB)'!F4="","",'જૂન સ્લેબ મુજબ (OLD SLAB)'!F4) | G4: =IF('જૂન સ્લેબ મુજબ (OLD SLAB)'!G4="","",'જૂન સ્લેબ મુજબ (OLD SLAB)'!G4) | H4: =IF('જૂન સ્લેબ મુજબ (OLD SLAB)'!H4="","",'જૂન સ્લેબ મુજબ (OLD SLAB)'!H4) | I4: =IF('જૂન સ્લેબ મુજબ (OLD SLAB)'!I4="","",'જૂન સ્લેબ મુજબ (OLD SLAB)'!I4) | J4: =IF('જૂન સ્લેબ મુજબ (OLD SLAB)'!J4="","",'જૂન સ્લેબ મુજબ (OLD SLAB)'!J4) | K4: =IF('જૂન સ્લેબ મુજબ (OLD SLAB)'!K4="","",'જૂન સ્લેબ મુજબ (OLD SLAB)'!K4) | L4: =IF('જૂન સ્લેબ મુજબ (OLD SLAB)'!L4="","",'જૂન સ્લેબ મુજબ (OLD SLAB)'!L4) | M4: =IF('જૂન સ્લેબ મુજબ (OLD SLAB)'!M4="","",'જૂન સ્લેબ મુજબ (OLD SLAB)'!M4) | ... O4: =IF('જૂન સ્લેબ મુજબ (OLD SLAB)'!O4="","",'જૂન સ્લેબ મુજબ (OLD SLAB)'!O4) | R4: Pan No. | V4: =IF('જૂન સ્લેબ મુજબ (OLD SLAB)'!V4="","",'જૂન સ્લેબ મુજબ (OLD SLAB)'!V4) | W4: =IF('જૂન સ્લેબ મુજબ (OLD SLAB)'!W4="","",'જૂન સ્લેબ મુજબ (OLD SLAB)'!W4) | X4: =IF('જૂન સ્લેબ મુજબ (OLD SLAB)'!X4="","",'જૂન સ્લેબ મુજબ (OLD SLAB)'!X4) | Y4: =IF('જૂન સ્લેબ મુજબ (OLD SLAB)'!Y4="","",'જૂન સ્લેબ મુજબ (OLD SLAB)'!Y4) | Z4: =IF('જૂન સ્લેબ મુજબ (OLD SLAB)'!Z4="","",'જૂન સ્લેબ મુજબ (OLD SLAB)'!Z4) | AA4: =IF('જૂન સ્લેબ મુજબ (OLD SLAB)'!AA4="","",'જૂન સ્લેબ મુજબ (OLD SLAB)'!AA4) | AB4: =IF('જૂન સ્લેબ મુજબ (OLD SLAB)'!AB4="","",'જૂન સ્લેબ મુજબ (OLD SLAB)'!AB4) | AC4: =IF('જૂન સ્લેબ મુજબ (OLD SLAB)'!AC4="","",'જૂન સ્લેબ મુજબ (OLD SLAB)'!AC4) | ... AE4: =IF('જૂન સ્લેબ મુજબ (OLD SLAB)'!AE4="","",'જૂન સ્લેબ મુજબ (OLD SLAB)'!AE4)
C6: Adhar No. | F6: =IF('જૂન સ્લેબ મુજબ (OLD SLAB)'!F6="","",'જૂન સ્લેબ મુજબ (OLD SLAB)'!F6) | G6: =IF('જૂન સ્લેબ મુજબ (OLD SLAB)'!G6="","",'જૂન સ્લેબ મુજબ (OLD SLAB)'!G6) | H6: =IF('જૂન સ્લેબ મુજબ (OLD SLAB)'!H6="","",'જૂન સ્લેબ મુજબ (OLD SLAB)'!H6) | I6: =IF('જૂન સ્લેબ મુજબ (OLD SLAB)'!I6="","",'જૂન સ્લેબ મુજબ (OLD SLAB)'!I6) | J6: =IF('જૂન સ્લેબ મુજબ (OLD SLAB)'!J6="","",'જૂન સ્લેબ મુજબ (OLD SLAB)'!J6) | K6: =IF('જૂન સ્લેબ મુજબ (OLD SLAB)'!K6="","",'જૂન સ્લેબ મુજબ (OLD SLAB)'!K6) | L6: =IF('જૂન સ્લેબ મુજબ (OLD SLAB)'!L6="","",'જૂન સ્લેબ મુજબ (OLD SLAB)'!L6) | M6: =IF('જૂન સ્લેબ મુજબ (OLD SLAB)'!M6="","",'જૂન સ્લેબ મુજબ (OLD SLAB)'!M6) | ... Q6: =IF('જૂન સ્લેબ મુજબ (OLD SLAB)'!Q6="","",'જૂન સ્લેબ મુજબ (OLD SLAB)'!Q6) | R6: Date of Birth | V6: =IF('જૂન સ્લેબ મુજબ (OLD SLAB)'!V6="","",'જૂન સ્લેબ મુજબ (OLD SLAB)'!V6) | W6: =IF('જૂન સ્લેબ મુજબ (OLD SLAB)'!W6="","",'જૂન સ્લેબ મુજબ (OLD SLAB)'!W6) | Y6: =IF('જૂન સ્લેબ મુજબ (OLD SLAB)'!Y6="","",'જૂન સ્લેબ મુજબ (OLD SLAB)'!Y6) | Z6: =IF('જૂન સ્લેબ મુજબ (OLD SLAB)'!Z6="","",'જૂન સ્લેબ મુજબ (OLD SLAB)'!Z6) | AB6: =IF('જૂન સ્લેબ મુજબ (OLD SLAB)'!AB6="","",'જૂન સ્લેબ મુજબ (OLD SLAB)'!AB6) | AC6: =IF('જૂન સ્લેબ મુજબ (OLD SLAB)'!AC6="","",'જૂન સ્લેબ મુજબ (OLD SLAB)'!AC6) | AD6: =IF('જૂન સ્લેબ મુજબ (OLD SLAB)'!AD6="","",'જૂન સ્લેબ મુજબ (OLD SLAB)'!AD6) | AE6: =IF('જૂન સ્લેબ મુજબ (OLD SLAB)'!AE6="","",'જૂન સ્લેબ મુજબ (OLD SLAB)'!AE6)
C8: (1) કર્મચારીનું પુરૂ નામ. | I8: =IF('જૂન સ્લેબ મુજબ (OLD SLAB)'!I8="","",'જૂન સ્લેબ મુજબ (OLD SLAB)'!I8) | X8: હોદ્દો | Z8: =IF('જૂન સ્લેબ મુજબ (OLD SLAB)'!Z8="","",'જૂન સ્લેબ મુજબ (OLD SLAB)'!Z8)
C9: (2) ઓફીસ/પે.કેન્દ્રનું નામ. | I9: =IF('જૂન સ્લેબ મુજબ (OLD SLAB)'!I9="","",'જૂન સ્લેબ મુજબ (OLD SLAB)'!I9) | V9: બેંક ખાતા નંબર | Z9: =IF('જૂન સ્લેબ મુજબ (OLD SLAB)'!Z9="","",'જૂન સ્લેબ મુજબ (OLD SLAB)'!Z9)
C10: (3) બેંકનું નામ. | I10: =IF('જૂન સ્લેબ મુજબ (OLD SLAB)'!I10="","",'જૂન સ્લેબ મુજબ (OLD SLAB)'!I10) | P10: શાખા. | R10: =IF('જૂન સ્લેબ મુજબ (OLD SLAB)'!R10="","",'જૂન સ્લેબ મુજબ (OLD SLAB)'!R10) | V10: બેંક IFSC Code: | Z10: =IF('જૂન સ્લેબ મુજબ (OLD SLAB)'!Z10="","",'જૂન સ્લેબ મુજબ (OLD SLAB)'!Z10)
C13: (1). | D13: આવક (વાર્ષિક પગાર સાથે) : | Z13: રૂ! | AA13: ='કપાટ પત્રક પેહલા ભરવુ '!E25 -> 0
C14: (2). | D14: બાદ (-) | F14: (A) | G14: સ્ટાન્ડર્ડ ડીડક્શન ( કલમ ૧૬ ) | R14: રૂ! | S14: 50000
F15: (B) | G15: વ્યવસાય વેરો | R15: રૂ! | S15: =AN15 -> 0 | AL15: ='કપાટ પત્રક પેહલા ભરવુ '!F18 -> 0 | AM15: 0 | AN15: =IF($M$1="હા",AL15,AM15) -> 0
F16: (C) | G16: મકાન લોનનું વ્યાજ ( ૨,૦૦,૦૦૦ સુધી) | R16: રૂ! | S16: =AD80 -> 0
F17: (D) | G17: અન્ય | R17: રૂ! | S17: 0
F18: (E) | G18: અન્ય | R18: રૂ! | S18: 0 | W18: (A+B+C+D+E) | Z18: રૂ! | AA18: =SUM(S14:V18) -> 50000
C19: (3). | D19: કોલમ (૧) બાદ કોલમ (૨) | Z19: રૂ! | AA19: =AA13-AA18 -> -50000 | AM19: =SUM(L21:N27)+SUM(X21:Z27) -> 0
C20: (4). | D20: બાદ કપાતો ( કલમ ૮૦ સી મુજબ )
D21: (A) | E21: જી.પી.એફ. | K21: રૂ! | L21: =AD86 -> 0 | P21: (H) | Q21: શિક્ષણ ફી (ભારતીય સંસ્થા) | W21: રૂ! | X21: 0 | AM21: =SUM(L21:N27) -> 0 | AN21: 50000 | AO21: =SUM(AM21:AN21) -> 50000
D22: (B) | E22: સી.પી.એફ. | K22: રૂ! | L22: =AD85 -> 0 | P22: (I) | Q22: પી.પી.એફ. | W22: રૂ! | X22: 0 | AM22: ='કપાટ પત્રક પેહલા ભરવુ '!H18 -> 0
D23: (C) | E23: જુથ વિમો | K23: રૂ! | L23: =AD84 -> 0 | P23: (J) | Q23: એન.એસ.સી. | W23: રૂ! | X23: 0
D24: (D) | E24: એલ.આઈ.સી.(પગારથી કપાત) | K24: રૂ! | L24: =AD83 -> 0 | P24: (K) | Q24: બેંક એફ. ડી. (૫ વર્ષની જ) | W24: રૂ! | X24: 0
D25: (E) | E25: એલ.આઈ.સી.ડાયરેક્ટ | K25: રૂ! | L25: 0 | P25: (L) | Q25: સુકન્યા સમૃધી યોજના | W25: રૂ! | X25: 0
D26: (F) | E26: મકાનલોન મુદ્દલ | K26: રૂ! | L26: =AD81 -> 0 | P26: (M) | Q26: ટેક્ષ સેવર મ્યુચુઅલ ફંડ | W26: રૂ! | X26: 0
D27: (G) | E27: પી.એલ.આઈ. | K27: રૂ! | L27: =AD82 -> 0 | P27: (N) | Q27: અન્ય | W27: રૂ! | X27: 0
C29: ( A to N ) કુલ સરવાળો દોઢ લાખ સુધી | P29: રૂ! | Q29: =AM33 -> 0 | AM29: =L21+AM22+L23+L24+L25+L26+L27 -> 0 | AN29: =SUM(X21:Z27) -> 0 | AO29: =SUM(AM29:AN29) -> 0
D31: (O) | E31: કલમ ૮૦ ડી મેડીક્લેઈમ ( ૨૫૦૦૦ સુધી ) | R31: રૂ! | S31: 0 | AM31: =IF(AO29>150000,150000,AO29) -> 0 | AN31: =IF(AO29>AM31,AO29-AM31,"") | AO31: =IF(AP31>AP31,AP31,AP31) -> 0 | AP31: =IF(AN31>AM22,AM22,AN31) -> 0
D32: (P) | E32: કલમ ૮૦ ડી.ડી.અપંગ આશ્રિત | R32: રૂ! | S32: 0 | AM32: =IF(AP31>50000,AM22-AO31,AM22-AP31) -> 0 | AN32: =IF(K1="ના",0,AO31) -> 0 | AO32: =IF(K1="ના",AM22,AM32) -> 0
D33: (Q) | E33: કલમ ૮૦ ડી.ડી.બી. ગંભીર રોગ | R33: રૂ! | S33: 0 | AM33: =IF(AM19<150000,AM19,AM31) -> 0
D34: (R) | E34: કલમ ૮૦ સી.સી.ડી. (2) એન.પી.એસ.(પગારના 10% ) | R34: રૂ! | S34: =AR2 -> 0
D35: (S) | E35: કલમ ૮૦ સીસીડી ૧ (બી) એન.પી.એસ.( રૂ. 50000/- સુધી) | R35: રૂ!
D36: (T) | E36: કલમ ૮૦ જી દાન (પાછળ સુચના ૫ પ્રમાણે) | R36: રૂ! | S36: 0
D37: (U) | E37: કલમ ૮૦ જી.જી.સી. રાજકીય પાર્ટીને દાન | R37: રૂ! | S37: 0
D38: (V) | E38: કલમ ૮૦ યુ અપંગ વ્યક્તિ | R38: રૂ! | S38: 0
D39: (W) | E39: કલમ ૮૦ ઈ ઉચ્ચ શિક્ષણ લોન વ્યાજ | R39: રૂ! | S39: 0 | W39: (A to W) કુલ સરવાળો | AB39: =SUM(Q29+S31+S32+S33+S34+S35+S36+S37+S38+S39) -> 0
C41: (5). | D41: કોલમ 3 બાદ કોલમ 4 | Q41: (ઈન્કમટેક્ષ પાત્ર રકમ ) | Y41: રૂ! | Z41: =AA19-AB39 -> -50000 | AG41: =SUM(AA19-AB39) -> -50000
C42: (6). | D42: ભરવા પાત્ર ઈન્કમટેક્ષ
E43: (1). | F43: રૂ! | G43: 3,00,000 | J43: સુધી ...................... | O43: 0 | P43: % | R43: રૂ! | S43: NIL | AL43: =IF($Z$41>300000,300000,$I$2) -> 0 | AM43: nil | AN43: nil
E44: (2). | F44: રૂ! | G44: 3,00,000 | J44: થી | K44: 6,00,000 સુધી 5 % | R44: રૂ! | S44: =IF(AN44="","",AN44) -> 0 | AL44: =IF(AM44<=0,0,AM44) -> 0 | AM44: =IF($Z$41<=600000,$Z$41-300000,300000) -> -350000 | AN44: =ROUND(AL44*5%,0) -> 0
E45: (3). | F45: રૂ! | G45: 6,00,000 | J45: થી | K45: 9,00,000 સુધી 10 % | R45: રૂ! | S45: =IF(AN45="","",AN45) -> 0 | AL45: =IF(AM45<=0,0,AM45) -> 0 | AM45: =IF($Z$41<=900000,$Z$41-600000,300000) -> -650000 | AN45: =ROUND(AL45*10%,0) -> 0
E46: (4). | F46: રૂ! | G46: 9,00,000 | J46: થી | K46: 12,00,000 સુધી 15 % | R46: રૂ! | S46: =IF(AN46="","",AN46) -> 0 | AL46: =IF(AM46<=0,0,AM46) -> 0 | AM46: =IF($Z$41<=1200000,$Z$41-900000,300000) -> -950000 | AN46: =ROUND(AL46*15%,0) -> 0
E47: (5). | F47: રૂ! | G47: 12,00,000 | J47: થી | K47: 15,00,000 સુધી 20 % | R47: રૂ! | S47: =IF(AN47="","",AN47) -> 0 | AL47: =IF(AM47<=0,0,AM47) -> 0 | AM47: =IF($Z$41<=1500000,$Z$41-1200000,300000) -> -1250000 | AN47: =ROUND(AL47*20%,0) -> 0
...

Sheet Sheet1
J1: 0
A2: =A3*A4 -> 0 | B2: =B3*B4 -> 0 | C2: =C3*C4 -> 0 | D2: =D3*D4 -> 0 | E2: =E3*E4 -> 0 | F2: =F3*F4 -> 0 | J2: 1 | K2: એક | L2: એક | M2: એક
A3: 10000000 | B3: 100000 | C3: 1000 | D3: 100 | E3: 1 | F3: 1 | J3: 2 | K3: બે | L3: બે | M3: બ
A4: =TRUNC(A9/A3) -> 0 | B4: =TRUNC((A9-A2)/B3) -> 0 | C4: =TRUNC((A9-A2-B2)/C3) -> 0 | D4: =TRUNC((A9-A2-B2-C2)/D3) -> 0 | E4: =TRUNC((A9-A2-B2-C2-D2)/E3) -> 0 | F4: =ROUND((A9-(SUM(A2:E2)))*100,0) -> 0 | J4: 3 | K4: ત્રણ | L4: ત્રણ | M4: ત્રણ
J5: 4 | K5: ચાર | L5: ચાર | M5: ચાર
A6: =IF(A4=0,"",VLOOKUP(A4,$J$1:$K$100,2)) | B6: =IF(B4=0,"",VLOOKUP(B4,$J$1:$K$100,2)) | C6: =IF(C4=0,"",VLOOKUP(C4,$J$1:$K$100,2)) | D6: =IF(D4=0,"",VLOOKUP(D4,$J$1:$M$100,4)) | E6: =IF(E4=0,"",VLOOKUP(E4,$J$1:$K$100,2)) | F6: =IF(F4=0,"",VLOOKUP(F4,$J$1:$K$100,2)) | J6: 5 | K6: પાંચ | L6: પાંચ | M6: પાંચ
A7: =IF(A6<>""," કરોડ ","") | B7: =IF(B6<>""," લાખ ","") | C7: =IF(C6<>""," હજાર ","") | D7: =IF(D6<>"","સો","") | E7: =IF(E6<>"","","") | F7: =IF(F6<>""," પૈસા ","") | G7: =IF(F6<>""," અને ","") | J7: 6 | K7: છ | L7: છ | M7: છ
J8: 7 | K8: સાત | L8: સાત | M8: સાત
A9: ='નવા સ્લેબ મુજબ (NEW SLAB)'!AA55 -> 0 | J9: 8 | K9: આઠ | L9: આઠ | M9: આઠ
J10: 9 | K10: નવ | L10: નવ | M10: નવ
J11: 10 | K11: દસ
A12: =CONCATENATE("અંકે રૂપિયા ",A6,A7,B6,B7,C6,C7,D6,D7,E6,E7,G7,F6,F7,A1,"પુરા") -> અંકે રૂપિયા પુરા | J12: 11 | K12: અગિયાર
J13: 12 | K13: બાર
J14: 13 | K14: તેર
A15: =A16*A17 -> 0 | B15: =B16*B17 -> 0 | C15: =C16*C17 -> 0 | D15: =D16*D17 -> 0 | E15: =E16*E17 -> 0 | F15: =F16*F17 -> 0 | J15: 14 | K15: ચૌદ
A16: 10000000 | B16: 100000 | C16: 1000 | D16: 100 | E16: 1 | F16: 1 | J16: 15 | K16: પંદર
A17: =TRUNC(A22/A16) -> 0 | B17: =TRUNC((A22-A15)/B16) -> 0 | C17: =TRUNC((A22-A15-B15)/C16) -> 0 | D17: =TRUNC((A22-A15-B15-C15)/D16) -> 0 | E17: =TRUNC((A22-A15-B15-C15-D15)/E16) -> 0 | F17: =ROUND((A22-(SUM(A15:E15)))*100,0) -> 0 | J17: 16 | K17: સોળ
J18: 17 | K18: સત્તર
A19: =IF(A17=0,"",VLOOKUP(A17,$J$1:$K$100,2)) | B19: =IF(B17=0,"",VLOOKUP(B17,$J$1:$K$100,2)) | C19: =IF(C17=0,"",VLOOKUP(C17,$J$1:$K$100,2)) | D19: =IF(D17=0,"",VLOOKUP(D17,$J$1:$M$100,4)) | E19: =IF(E17=0,"",VLOOKUP(E17,$J$1:$K$100,2)) | F19: =IF(F17=0,"",VLOOKUP(F17,$J$1:$K$100,2)) | J19: 18 | K19: અઢાર
A20: =IF(A19<>""," કરોડ ","") | B20: =IF(B19<>""," લાખ ","") | C20: =IF(C19<>""," હજાર ","") | D20: =IF(D19<>"","સો","") | E20: =IF(E19<>"","","") | F20: =IF(F19<>""," પૈસા ","") | G20: =IF(F19<>""," અને ","") | J20: 19 | K20: ઓગણિસ
J21: 20 | K21: વીસ
A22: ='જૂન સ્લેબ મુજબ (OLD SLAB)'!AA55 -> 0 | J22: 21 | K22: એકવીસ
J23: 22 | K23: બાવીસ
J24: 23 | K24: ત્રેવીસ
A25: =CONCATENATE("અંકે રૂપિયા ",A19,A20,B19,B20,C19,C20,D19,D20,E19,E20,G20,F19,F20,A14,"પુરા") -> અંકે રૂપિયા પુરા | J25: 24 | K25: ચોવીસ
J26: 25 | K26: પચ્ચીસ
J27: 26 | K27: છવ્વીસ
A28: =A29*A30 -> 0 | B28: =B29*B30 -> 0 | C28: =C29*C30 -> 0 | D28: =D29*D30 -> 100 | E28: =E29*E30 -> 44 | F28: =F29*F30 -> 0 | J28: 27 | K28: સત્યાવીસ
A29: 10000000 | B29: 100000 | C29: 1000 | D29: 100 | E29: 1 | F29: 1 | J29: 28 | K29: અઠ્યાવીસ
A30: =TRUNC(A35/A29) -> 0 | B30: =TRUNC((A35-A28)/B29) -> 0 | C30: =TRUNC((A35-A28-B28)/C29) -> 0 | D30: =TRUNC((A35-A28-B28-C28)/D29) -> 1 | E30: =TRUNC((A35-A28-B28-C28-D28)/E29) -> 44 | F30: =ROUND((A35-(SUM(A28:E28)))*100,0) -> 0 | J30: 29 | K30: ઓગણત્રીસ
J31: 30 | K31: ત્રીસ
A32: =IF(A30=0,"",VLOOKUP(A30,$J$1:$K$100,2)) | B32: =IF(B30=0,"",VLOOKUP(B30,$J$1:$K$100,2)) | C32: =IF(C30=0,"",VLOOKUP(C30,$J$1:$K$100,2)) | D32: =IF(D30=0,"",VLOOKUP(D30,$J$1:$M$100,4)) -> એક | E32: =IF(E30=0,"",VLOOKUP(E30,$J$1:$K$100,2)) -> ચુંમાલીસ | F32: =IF(F30=0,"",VLOOKUP(F30,$J$1:$K$100,2)) | J32: 31 | K32: એકત્રીસ
A33: =IF(A32<>""," કરોડ ","") | B33: =IF(B32<>""," લાખ ","") | C33: =IF(C32<>""," હજાર ","") | D33: =IF(D32<>"","સો","") -> સો | E33: =IF(E32<>"","","") | F33: =IF(F32<>""," પૈસા ","") | G33: =IF(F32<>""," અને ","") | J33: 32 | K33: બત્રીસ
J34: 33 | K34: તેત્રીસ
A35: 144 | J35: 34 | K35: ચોત્રીસ
J36: 35 | K36: પાંત્રીસ
J37: 36 | K37: છત્રીસ
A38: =CONCATENATE("અંકે રૂપિયા ",A32,A33,B32,B33,C32,C33,D32,D33,E32,E33,G33,F32,F33,A27,"પુરા") -> અંકે રૂપિયા એકસોચુંમાલીસ પુરા | J38: 37 | K38: સાડત્રીસ
J39: 38 | K39: આડત્રીસ
J40: 39 | K40: ઓગણચાલીસ
...

Sheet સૂચના વાંચી ફોરમ ભરવું 
A1: તાલુકા પંચાયત શિક્ષણ શાખા જંબુસર
A4: સૂચના મુજબ ફોર્મ ભરવુ
A5: ૧. આ ફોર્મ સાથે આપેલ ગુજરાતી ફૉન્ટસ ઇન્સ્ટોલ કરવા.
A6: ૨. સો પ્રથમ ફોર્મ ની શરૂઆત કપાત પત્રક કૉલમ થી ચાલુ કરવી જેમકે પગાર,એરિયર્સ,રોકાણ,ટેક્સ,વગેરે ની માહિતી ભરવી.
A7: ૩. પર્સનલ માહિતી જેમકે નામ,પાનકાર્ડ નંબર,આધાર કાર્ડ નંબર,મોબાઈલ નંબર,બેન્ક માહિતી વગેરે ની માહિતી જાતે ભરવાની રહેશે.
A8: ૪. C.P.F. ત્થા G.P.F.ત્થા NPS રોકાણ હોય તો તેના ઓપ્શન ફિલ કરવાની રહેશે.
A9: ૫. નવા સ્લેબ મુજબ સ્ટાન્ડર્ડ ડિડક્શન ૫૦૦૦૦/- સિવાય અન્ય કોઈપણ રોકાણ બાદ મળશે નહિ.
A10: ૬. કપાત પત્રક કૉલમ માં વિગત ભરવાથી નવા ત્થા જૂન સ્લેબ ની ગણતરી ઓટો ફિલ થઈ જશે.
A11: ૭. બેન્ક વ્યાજ ત્થા ફિક્સ ડિપોજીત ના વ્યાજ ની રકમ આ ફોર્મ માં દર્શાવાની નથી ઇન્કમટેક્સ રિટર્ન ફાઇલ ના સમયે બતાવવાની રહેશે.
A14: ફોર્મ સાથે જરૂરી ડોક્યુમેન્ટ
A15: ૧. પાન કાર્ડ ઝેરોક્ષ, આધારકાર્ડ ઝેરોક્ષ , બેન્ક પાસબુક ઝેરોક્ષ
A16: ૨. તમામ રોકાણની ઝેરોક્ષ કોપી ફરજીયાત જોડવી(૦૧/૦૪/૨૦૨૩ થી ૩૧/૦૩/૨૦૨૪)
... A25: આમોદ
A26: 9904297366
