Workbook

Sheet સુચના 
C2: તાલુકા પંચાયત શિક્ષણ શાખા આમોદ
C4: સુચના
C5: સૌ પ્રથમ પત્રક ભરતા પેહલા શરૂઆત જુના સ્લેબ થી ચાલુ કરવી.
C6: બધી વિગત ચકાસણી કરી ભરવી.
C7: કોઈ વિગત અધૂરી રાખશો નહી જેથી પત્રક ભરવામાં પ્રોબ્લેમ થાય.
C8: જુના સ્લેબમા પર્સનલ માહિતી,કુલ પગાર,કપાત,ટેકસ,વિગેરે માહિતી ફરજિયાત ભરવાની રહેશે.
C9: નવા સ્લેબ માં કોઈ પણ માહિતી દાખલ કરવાની રહેશે નહિ.
C10: જુના સ્લેબ મુજબ આપેલ માહિતી મુજબ નવા સ્લેબ માં ઓટો માહિતી આવી જશે.
C11: આ સીટ માં જ્યારે કોઈ બીજા વ્યક્તિ ની ગણતરી કરો ત્યારે સીટ ની માહિતી કાઢી નાખશો.
C13: TPEO AMOD
C14: શબ્બીરભાઈ સુલેમાન સાપા

Sheet OLD Regime Page 1 
A1: તાલુકા પંચાયત આમોદ (શિક્ષણ શાખા)
A2: આવકવેરા ગણતરી પત્રક (જુના સ્લેબ મુજબ) ( OLD REGIME )
A3: નાણાકીય વર્ષ | B3: ૨૦૨૪ / ૨૫ | L3: આકારણી વર્ષ | N3: ૨૦૨૫/ ૨૬
A4: કર્મચારીનું નામ: | L4: પે.સેન્ટર નું નામ
A5: પિતાનું પુરૂં નામ: | L5: જન્મ તારીખ:
A6: પ્રા. શાળા નું નામ: | L6: શાળા નો પીનકોડ નંબર:
A7: રહેઠાણ નું પૂરૂં સરનામું | L7: રહેઠાણ નો પીનકોડ નંબર
L8: મોબાઈલ નં.
A9: ઇન્કમટેક્ષ PAN No | L9: આધાર કાર્ડ નં.
A10: બેન્ક એકાઉન્ટ નંબર | L10: બેંક બ્રાન્ચ
A11: ઈ.મેલ આઇ. ડી | L11: IFSC CODE
A12: વર્ષ ૨૦૨૪ / ૨૫ નો માસવાર પગાર | B12: કુલ પગાર | F12: જી. પી. ફંડ | I12: C P F | K12: વ્યવસાય વેરો | L12: જૂથ વીમો | M12: L.I.C. | N12: મકાન લોન
I13: (NDCPS) | N13: મુદ્દલ | O13: વ્યાજ
A14: માર્ચ પેઇડ એપ્રિલ ૨૪ | B14: 0 | F14: 0 | I14: 0 | K14: 0 | L14: 0 | M14: 0 | O14: 0
A15: એપ્રિલ પેઇડ મે ૨૪ | B15: 0 | F15: 0 | I15: 0 | K15: 0 | L15: 0 | M15: 0 | O15: 0
A16: મેં પેઇડ જૂન ૨૪ | B16: 0 | F16: 0 | I16: 0 | K16: 0 | L16: 0 | M16: 0 | O16: 0
A17: જૂન પેઇડ જુલાઈ ૨૪ | B17: 0 | F17: 0 | I17: 0 | K17: 0 | L17: 0 | M17: 0 | O17: 0
A18: જુલાઈ પેઇડ ઓગસ્ટ ૨૪ | B18: 0 | F18: 0 | I18: 0 | K18: 0 | L18: 0 | M18: 0 | O18: 0
A19: ઓગસ્ટ પેઇડ સપ્ટેમ્બર ૨૪ | B19: 0 | F19: 0 | I19: 0 | K19: 0 | L19: 0 | M19: 0 | O19: 0
A20: સપ્ટેમ્બર પેઇડ ઓક્ટો ૨૪ | B20: 0 | F20: 0 | I20: 0 | K20: 0 | L20: 0 | M20: 0 | O20: 0
A21: ઓક્ટો પેઇડ ઓક્ટો ૨૪ | B21: 0 | F21: 0 | I21: 0 | K21: 0 | L21: 0 | M21: 0 | O21: 0
A22: નવે પેઇડ ડિસે ૨૪ | B22: 0 | F22: 0 | I22: 0 | K22: 0 | L22: 0 | M22: 0 | O22: 0
A23: ડિસે પેઇડ જાન્યુ. ૨૫ | B23: 0 | F23: 0 | I23: 0 | K23: 0 | L23: 0 | M23: 0 | O23: 0
A24: જાન્યુ. પેઈડ ફેબ્રુ. ૨૫ | B24: 0 | F24: 0 | I24: 0 | K24: 0 | L24: 0 | M24: 0 | O24: 0
A25: ફેબ્રુઆરી પેઇડ માર્ચ ૨૫ | B25: 0 | F25: 0 | I25: 0 | K25: 0 | L25: 0 | M25: 0 | O25: 0
A26: મોંઘવારી તફાવત
A27: ૦૧/૦૭/૨૩ થી ૨૯/૦૨/૨૪ ( ૪ % ) | B27: 0
A28: ૦૧/૦૧/૨૪ થી ૩૦/૬/૨૪ (૪ % ) | B28: 0
A29: ૧/૦૭/૨૪ થી ૩૦/૧૧/૨૪ ( ૩ % ) | B29: 0
A30: ઉ.પ.ધો. તફાવત બિલ | B30: 0
A31: અન્ય આવક/પુરવણી બિલ LTC | B31: 0
A33: કુલ | B33: =SUM(B14:E32) -> 0 | F33: =SUM(F14:H31) -> 0 | I33: =SUM(I14:J31) -> 0 | K33: =SUM(K14:K31) -> 0 | L33: =SUM(L14:L31) -> 0 | M33: =SUM(M14:M31) -> 0 | N33: =SUM(N14:N31) -> 0 | O33: =SUM(O14:O31) -> 0
A34: [A] પગારની કુલ આવક | M34: =B33 -> 0 | Q34: =I33 -> 0
A35: બાદ: કરમુક્ત ભથ્થા અને કપાતો (US/17) | Q35: 50000
A36: (૧) કન્વેઅંસ એલા.(અપંગ કર્મચારી) | K36: 0 | Q36: =Q34-Q35 -> -50000
A37: (૨) સ્ટાડૅડ ડિડકશન (તમામને રૂ.૫૦૦૦૦)(US/16) | K37: 50000
A38: (૩) વ્યવસાય વેરો | K38: =K33 -> 0
A39: કુલ કપાત: (૧ થી ૩) | K39: =SUM(K36:L38) -> 50000
A40: ચોખ્ખી પગારની આવક | M40: =M34-K39 -> -50000
A41: બાદ: મકાન લોન વ્યાજ [U/S 24 (2)] મહત્તમ રૂ. ૨૦૦૦૦૦/- સુધી | M41: 0 | O41: =IF(M41>=200000,(200000),IF(M41<200000,M41)) -> 0
...

Sheet OLD Regime Page 2 
A1: કુલ ગ્રોસ આવક: [B] મુજબ | I1: ='OLD Regime Page 1 '!M43 -> -50000
A2: [C] આવકમાંથી મળતી કપાત [U/S80-C]
A3: 1.જી. પી. એફ | E3: ='OLD Regime Page 1 '!F33 -> 0 | G3: ખાસ સુચના: (૧) ફોર્મ માં તમામ માહિતી સંપૂર્ણ ચોકસાઈથી ભરવી, કોઇ માહિતી અધૂરી રાખવી નહીં. આચાર્ય સાહેબ શ્રી એ તમામ વિગતો તપાસી તેમાં સહી સિક્કા કરવાના રહેશે
A4: 2. જૂથ વીમો | E4: ='OLD Regime Page 1 '!L33 -> 0
A5: 3 એલ.આઈ.સી પ્રીમિયમ (પગારમાંથી) | E5: ='OLD Regime Page 1 '!M33 -> 0
A6: 4 એલ.આઈ.સી પ્રીમિયમ (પગાર કપાત સિવાય) | E6: 0
A7: 5. પી.એલ.આઈ પ્રીમિયમ | E7: 0
A8: 6 મકાન લોન મુદ્દલ | E8: 0
A9: 7 . એન. એસ. સી. રોકાણ | E9: 0
A10: 8 મ્યુચ્યુઅલ ફંડ (ઇ.એલ.એસ.એસ.) | E10: 0
A11: 9 બજાજ/કોટક/આઇ.સી.આઇ.સી.આઇ વીમો | E11: 0
A12: 10. સુકન્યા સમૃદ્ધિ યોજના | E12: 0
A13: 11. પી.પી.એફ. રોકાણ | E13: 0
A14: 12. બાળકોની શિક્ષણ ફી | E14: 0
A15: કુલ (મહત્તમ મર્યાદા રૂ.૧, ૫૦,૦૦૦/-) | E15: =SUM(E3:F14) -> 0 | I15: =IF(E15>=150000,(150000),IF(E15<150000,E15)) -> 0
A16: [D] બાકી આવક (B-C) | I16: =I1-I15 -> -50000
A17: [E] (U/S 80) મુજબ બાદ મળતી અન્ય કપાત
A18: 1. મેડીકલેમ પ્રીમિયમ (રૂ.૨૫,૦૦૦ સુધી) | E18: 80 D | F18: 0
A19: 2.પેરેન્ટ્સ મેડીકલેમ પ્રીમિયમ (રૂ.૨૫,૦૦૦ સુધી) | E19: 80 D | F19: 0
A20: 3. અંધ અપંગ કર્મચારીને મળતી ખાસ કપાત | E20: 80 U | F20: 0
A21: (૪૦ ટકા અશક્તતા હોય તો રૂ.૭૫,૦૦૦. ૮૦ ટકા હોય તો ૧,૨૫,૦૦૦
A22: 4.NPS અલગ થી રોકાણ કર્યું હોય તો (મહત્તમ રૂ.૫૦,૦૦૦)80CCD1B | F22: 0
A23: 5. એજ્યુકેશન લોન 80 E | F23: 0
A24: 6. મુખ્ય મંત્રી રાહત ફંડ | F24: 0
A25: 7. NDCPS મા સરકાર શ્રી નો હિસ્સો ( 80 CCD- 2 ) | F25: ='OLD Regime Page 1 '!I33 -> 0
A26: 8. 80 G (દાન) હેઠળ મળતી કપાત: કુલ કરપાત્ર આવક ના ૧૦% સુધી રોકણ કરી કરી શકો | D26: ખરેખર આપેલ દાન | F26: ૫૦% મુજબ બાદ મળવાપાત્ર રકમ | I26: દાન આપેલ સંસ્થાનો પાનકાર્ડ નંબર ફરજિયાત લખો
A27: દાન આપેલ સંસ્થાનું નામ: | D27: 0 | F27: =D27/2 -> 0
A29: કુલ કપાત:(એફ 1 થી 8 નો સરવાળો કરવો) | F29: =SUM(F18:G28) -> 0
A30: [F] કરપાત્ર આવક [D] - [E] | I30: =I16-F29 -> -50000
A31: કરપાત્ર આવક: (નજીકના ૧૦ રૂપિયામાં) | I31: =ROUND(I30,-1) -> -50000
A32: [G] આવક વેરાની રકમ
A33: કરપાત્ર આવકની ગણતરી | I33: માસ | K33: ટેક્ષની કપાત
A34: ૧. પ્રથમ રૂ.૨,૫૦,૦૦૦ સુધી | F34: NIL | I34: માર્ચ પેઇડ એપ્રિલ ૨૪ | K34: 0
A35: ૨. રૂ.૨,૫૦,૦૦૦ થી ૫,૦૦,૦૦૦ સુધીની રકમના ૫ % | F35: =IF(I31<=250000,0,IF(I31>=500000,(500000-250000)*5/100,IF(I31<500000,(I31-250000)*5/100, ))) -> 0 | I35: એપ્રિલ પેઇડ મે ૨૪ | K35: 0
A36: ૩. રૂ. ૫,૦૦,૦૦૧ થી ૧૦,૦૦,૦૦૦ સુધીની રકમના ૨૦ % | F36: =IF(I31>=1000000,100000,IF(I31>500000,(I31-500000)*20/100,IF(I31<=500000,0))) -> 0 | I36: મેં પેઇડ જૂન ૨૪ | K36: 0
A37: ૪. રૂ.૧૦,૦૦,૦૦૧ થી વધુ પર ૩૦% | F37: =IF(I31>1000000,(I31-1000000)*30/100,IF(I31<1000000,0)) -> 0 | I37: જૂન પેઇડ જુલાઈ ૨૪ | K37: 0
A38: ઉપરની ગણતરી મુજબ આવકવેરાની કુલ રકમ [G] મુજબ | F38: =SUM(F35:F37) -> 0 | I38: જુલાઈ પેઇડ ઓગસ્ટ ૨૪ | K38: 0
A39: બાદ રિબેટ 87 A (મહત્તમ રૂ. ૧૨,૫૦૦) કરપાત્ર આવક (G) મુજબ પાંચ લાખ સુધી હોય તો જ | F39: =IF(I31<=250000,0,IF(I31>500000,0,IF(I31<500000,(I31-250000)*5/100))) -> 0 | I39: ઓગસ્ટ પેઇડ સપ્ટેમ્બર ૨૪ | K39: 0
I40: સપ્ટેમ્બર પેઇડ ઓક્ટો ૨૪ | K40: 0
A41: બાકી આવકવેરો | F41: =F38-F39 -> 0 | I41: ઓક્ટો પેઇડ ઓક્ટો ૨૪ | K41: 0
...

Sheet New Regime Page 1
A3: તાલુકા પંચાયત આમોદ (શિક્ષણ શાખા)
A4: આવકવેરા ગણતરી પત્રક (નવા સ્લેબ મુજબ) ( NEW REGIME )
A5: નાણાકીય વર્ષ | B5: ૨૦૨૪ / ૨૫ | L5: આકારણી વર્ષ | N5: ૨૦૨૫/ ૨૬
A6: કર્મચારીનું નામ: | B6: ='OLD Regime Page 1 '!B4:K4 -> 0 | L6: પે.સેન્ટર નું નામ | N6: ='OLD Regime Page 1 '!N4:O4 -> 0
A7: પિતાનું પુરૂં નામ: | B7: ='OLD Regime Page 1 '!B5:K5 -> 0 | L7: જન્મ તારીખ: | N7: ='OLD Regime Page 1 '!N5:O5 -> 0
A8: પ્રા. શાળા નું નામ: | B8: ='OLD Regime Page 1 '!B6:K6 -> 0 | L8: શાળા નો પીનકોડ નંબર: | N8: ='OLD Regime Page 1 '!N6:O6 -> 0
A9: રહેઠાણ નું પૂરૂં સરનામું | B9: ='OLD Regime Page 1 '!B7:K7 -> 0 | L9: રહેઠાણ નો પીનકોડ નંબર | N9: ='OLD Regime Page 1 '!N7:O7 -> 0
L10: મોબાઈલ નં. | M10: ='OLD Regime Page 1 '!M8:O8 -> 0
A11: ઇન્કમટેક્ષ PAN No | B11: ='OLD Regime Page 1 '!B9 -> 0 | L11: આધાર કાર્ડ નં. | M11: ='OLD Regime Page 1 '!M9 -> 0
A12: બેન્ક એકાઉન્ટ નંબર | B12: ='OLD Regime Page 1 '!B10:K10 -> 0 | L12: બેંક બ્રાન્ચ | M12: ='OLD Regime Page 1 '!M10:O10 -> 0
A13: ઈ.મેલ આઇ. ડી | B13: ='OLD Regime Page 1 '!B11:K11 -> 0 | L13: IFSC CODE | M13: ='OLD Regime Page 1 '!M11:O11 -> 0
A14: વર્ષ 2024 / 25 નો માસવાર પગાર | B14: કુલ પગાર | F14: NDCPS કપાત
A16: માર્ચ પેઇડ એપ્રિલ 24 | B16: =SUM('OLD Regime Page 1 '!B14:E14) -> 0 | F16: =SUM('OLD Regime Page 1 '!I14:J14) -> 0
A17: એપ્રિલ પેઇડ મે 24 | B17: =SUM('OLD Regime Page 1 '!B15:E15) -> 0 | F17: =SUM('OLD Regime Page 1 '!I15:J15) -> 0
A18: મેં પેઇડ જૂન 24 | B18: =SUM('OLD Regime Page 1 '!B16:E16) -> 0 | F18: =SUM('OLD Regime Page 1 '!I16:J16) -> 0
A19: જૂન પેઇડ જુલાઈ 24 | B19: =SUM('OLD Regime Page 1 '!B17:E17) -> 0 | F19: =SUM('OLD Regime Page 1 '!I17:J17) -> 0
A20: જુલાઈ પેઇડ ઓગસ્ટ 24 | B20: =SUM('OLD Regime Page 1 '!B18:E18) -> 0 | F20: =SUM('OLD Regime Page 1 '!I18:J18) -> 0
A21: ઓગસ્ટ પેઇડ સપ્ટેમ્બર 24 | B21: =SUM('OLD Regime Page 1 '!B19:E19) -> 0 | F21: =SUM('OLD Regime Page 1 '!I19:J19) -> 0
A22: સપ્ટેમ્બર પેઇડ ઓક્ટો 24 | B22: =SUM('OLD Regime Page 1 '!B20:E20) -> 0 | F22: =SUM('OLD Regime Page 1 '!I20:J20) -> 0
A23: ઓક્ટો પેઇડ નવે 24 | B23: =SUM('OLD Regime Page 1 '!B21:E21) -> 0 | F23: =SUM('OLD Regime Page 1 '!I21:J21) -> 0
A24: નવે પેઇડ ડિસે 24 | B24: =SUM('OLD Regime Page 1 '!B22:E22) -> 0 | F24: =SUM('OLD Regime Page 1 '!I22:J22) -> 0
A25: ડિસે પેઇડ જાન્યુ. 25 | B25: =SUM('OLD Regime Page 1 '!B23:E23) -> 0 | F25: =SUM('OLD Regime Page 1 '!I23:J23) -> 0
A26: જાન્યુ. પેઈડ ફેબ્રુ. 25 | B26: =SUM('OLD Regime Page 1 '!B24:E24) -> 0 | F26: =SUM('OLD Regime Page 1 '!I24:J24) -> 0
A27: ફેબ્રુઆરી પેઇડ માર્ચ 25 | B27: =SUM('OLD Regime Page 1 '!B25:E25) -> 0 | F27: =SUM('OLD Regime Page 1 '!I25:J25) -> 0
A28: મોંઘવારી તફાવત
A29: ૦૧/૦૭/૨૩ થી ૨૯/૦૨/૨૪ ( ૪ % ) | B29: =SUM('OLD Regime Page 1 '!B27:E27) -> 0
A30: ૦૧/૦૧/૨૪ થી ૩૦/૬/૨૪ (૪ % ) | B30: =SUM('OLD Regime Page 1 '!B28:E28) -> 0
A31: ૧/૦૭/૨૪ થી ૩૦/૧૧/૨૪ ( ૩ % ) | B31: =SUM('OLD Regime Page 1 '!B29:E29) -> 0
A32: ઉ.પ.ધો. તફાવત બિલ | B32: =SUM('OLD Regime Page 1 '!B30:E30) -> 0
A33: અન્ય આવક / પુરવણી બિલ | B33: =SUM('OLD Regime Page 1 '!B31:E31) -> 0
A35: કુલ | B35: =SUM(B16:E34) -> 0 | F35: =SUM(F16:F27) -> 0
A36: [A] પગારની કુલ આવક | M36: =B35 -> 0
A37: બાદ
A38: [B] (૨) સ્ટાડૅડ ડિડકશન (તમામને રૂ.૭૫૦૦૦)(US/16) | K38: 75000 | M38: =M36-K38 -> -75000

Sheet New Regime Page 2
A1: કુલ ગ્રોસ આવક: [B] મુજબ | I1: =SUM('New Regime Page 1'!M38:O38) -> -75000
A2: [C] (U/S 80 CCD- 2) મુજબ બાદ મળતી કપાત | F2: ='New Regime Page 1'!F35:J35 -> 0
A3: ( 1 ) NDCPS મા સરકાર શ્રી નો હિસ્સો | I3: =F2 -> 0
A4: [D] કરપાત્ર આવક [B] - [C] | I4: =I1-I3 -> -75000
A5: કરપાત્ર આવક: (નજીકના ૧૦ રૂપિયામાં) | I5: =ROUND(I4,0) -> -75000
A6: [E] આવક વેરાની રકમ
A7: કરપાત્ર આવકની ગણતરી | I7: માસ | K7: ટેક્ષની કપાત
A8: ૧. પ્રથમ રૂ.3,00,000 સુધી | F8: NIL | I8: માર્ચ પેઇડ એપ્રિલ ૨૪ | K8: ='OLD Regime Page 2 '!K34:L34 -> 0
A9: ૨. રૂ.૩,૦૦,૦૦૦ થી 7,૦૦,૦૦૦ સુધીની રકમના ૫ % | F9: =IF(I5<=300000,0,IF(I5>=700000,(700000-300000)*5/100,IF(I5<700000,(I5-300000)*5/100, ))) -> 0 | I9: એપ્રિલ પેઇડ મે ૨૪ | K9: ='OLD Regime Page 2 '!K35:L35 -> 0
A10: ૩. રૂ. 7,00,000 થી 10,00,000 સુધીની રકમના ૧૦ % | F10: =IF(I5>=1000000,30000,IF(I5>700000,(I5-700000)*10/100,IF(I5<700000,0))) -> 0 | I10: મેં પેઇડ જૂન ૨૪ | K10: ='OLD Regime Page 2 '!K36:L36 -> 0
A11: ૪. રૂ.10,00૦૦,૦૦૧ થી 12,00,000 વધુ પર 15% | F11: =IF(I5>=1200000,30000,IF(I5>1000000,(I5-1000000)*15/100,IF(I5<1000000,0))) -> 0 | I11: જૂન પેઇડ જુલાઈ ૨૪ | K11: ='OLD Regime Page 2 '!K37:L37 -> 0
A12: 5. રૂ.12,00,૦૦૧ થી 15,00,000 વધુ પર 2૦% | F12: =IF(I5>=1500000,60000,IF(I5>1200000,(I5-1200000)*20/100,IF(I5<1200000,0))) -> 0 | I12: જુલાઈ પેઇડ ઓગસ્ટ ૨૪ | K12: ='OLD Regime Page 2 '!K38:L38 -> 0
A13: 6 રૂ.15,00૦૦,૦૦૧ થી વધુ પર 3૦% | F13: =IF(I5>1500000,(I5-1500000)*30/100,IF(I31<1500000,0)) -> 0 | I13: ઓગસ્ટ પેઇડ સપ્ટેમ્બર ૨૪ | K13: ='OLD Regime Page 2 '!K39:L39 -> 0
A14: ઉપરની ગણતરી મુજબ આવકવેરાની કુલ રકમ [E] મુજબ | F14: =SUM(F9:G13) -> 0 | I14: સપ્ટેમ્બર પેઇડ ઓક્ટો ૨૪ | K14: ='OLD Regime Page 2 '!K40:L40 -> 0
A15: બાદ : 7,00,000 થી ઓછી કરપાત્ર આવક હોય તો ટેક્સ રાહત 87/A મુજબ રૂ/. 20000/- | F15: =IF(I5>700000,0,IF(I5=700000,20000,IF(I5<7000000,F14))) -> 0 | I15: ઓક્ટો પેઇડ ઓક્ટો ૨૪ | K15: ='OLD Regime Page 2 '!K41:L41 -> 0
I16: નવે પેઇડ ડિસે ૨૪ | K16: ='OLD Regime Page 2 '!K42:L42 -> 0
A17: બાકી આવકવેરો | F17: =F14-F15 -> 0 | I17: ડિસે પેઇડ જાન્યુ. ૨૫ | K17: ='OLD Regime Page 2 '!K43:L43 -> 0
A18: Marignal Relief 7,00,001 થી 7,22,222 ની આવક માટે | F18: =IF(F15<0,0,IF(F14>I5-700000,(I5-700000)-F14,0)) -> -775000 | I18: જાન્યુ પેઇડ ફેબ્રુઆરી ૨૫ | K18: ='OLD Regime Page 2 '!K44:L44 -> 0
A19: Marignal Relief બાદ કરતા ભરવાપાત્ર ટેક્સ | F19: =+F17+F18 -> -775000 | I19: ફેબ્રુ પેઇડ માર્ચ ૨૫ | K19: ='OLD Regime Page 2 '!K45:L45 -> 0
A20: [F] ઉમેરો એજ્યુકેશન સેસ 3% તથા મેડીકલ સેસ 1% કુલ 4 % | F20: =+F19*0.04 -> -31000 | I20: ઉપ ધો એડ. ટેક્સ | K20: ='OLD Regime Page 2 '!K46:L46 -> 0
A21: [G] ભરવાપાત્ર આવકવેરાની રકામ | F21: =+F19+F20 -> -806000 | I21: અન્ય કપાયેલ ટેક્ષ | K21: ='OLD Regime Page 2 '!K47:L47 -> 0
A22: [H] કલમ ૮૯ (૧) ઇ મુજબ બાદ જો હોય તો | F22: 0 | I22: કુલ | K22: =SUM(K8:L21) -> 0
A23: [I] કલમ ૮૯ (૧) ઇ મુજબ બાદ કર્યા બાદ રહેતી રકમ | F23: =F21-F22 -> -806000
A24: [J]બાદ: ચાલુ વર્ષમાં કપાત કરેલ /એડવાન્સ ટેક્ષ | F24: =SUM(K22) -> 0
A25: [K] બાકી રહેતા આવક વેરાની રકમ | F25: =F23-F24 -> -806000
I26: કર્મચારી ની સહી તથા હોદ્દો
A27: સ્થળ
A28: તારીખ | I28: આચાર્યની સહી
